[2024-10-04T05:10:31.826+0000] {taskinstance.py:1979} INFO - Dependencies all met for dep_context=non-requeueable deps ti=<TaskInstance: Gold_training_Pipeline.model_training manual__2024-10-04T05:09:56.589972+00:00 [queued]>
[2024-10-04T05:10:31.911+0000] {taskinstance.py:1979} INFO - Dependencies all met for dep_context=requeueable deps ti=<TaskInstance: Gold_training_Pipeline.model_training manual__2024-10-04T05:09:56.589972+00:00 [queued]>
[2024-10-04T05:10:31.912+0000] {taskinstance.py:2193} INFO - Starting attempt 4 of 4
[2024-10-04T05:10:31.923+0000] {taskinstance.py:2217} INFO - Executing <Task(PythonOperator): model_training> on 2024-10-04 05:09:56.589972+00:00
[2024-10-04T05:10:31.930+0000] {standard_task_runner.py:60} INFO - Started process 2281 to run task
[2024-10-04T05:10:31.932+0000] {standard_task_runner.py:87} INFO - Running: ['***', 'tasks', 'run', 'Gold_training_Pipeline', 'model_training', 'manual__2024-10-04T05:09:56.589972+00:00', '--job-id', '244', '--raw', '--subdir', 'DAGS_FOLDER/gold_training_pipeline.py', '--cfg-path', '/tmp/tmpzzjuyt73']
[2024-10-04T05:10:31.934+0000] {standard_task_runner.py:88} INFO - Job 244: Subtask model_training
[2024-10-04T05:10:31.965+0000] {task_command.py:423} INFO - Running <TaskInstance: Gold_training_Pipeline.model_training manual__2024-10-04T05:09:56.589972+00:00 [running]> on host 7277d8e72c00
[2024-10-04T05:10:32.015+0000] {taskinstance.py:2513} INFO - Exporting env vars: AIRFLOW_CTX_DAG_OWNER='sdeshan' AIRFLOW_CTX_DAG_ID='Gold_training_Pipeline' AIRFLOW_CTX_TASK_ID='model_training' AIRFLOW_CTX_EXECUTION_DATE='2024-10-04T05:09:56.589972+00:00' AIRFLOW_CTX_TRY_NUMBER='4' AIRFLOW_CTX_DAG_RUN_ID='manual__2024-10-04T05:09:56.589972+00:00'
[2024-10-04T05:10:32.029+0000] {taskinstance.py:2731} ERROR - Task failed with exception
Traceback (most recent call last):
  File "/home/airflow/.local/lib/python3.8/site-packages/airflow/models/taskinstance.py", line 444, in _execute_task
    result = _execute_callable(context=context, **execute_callable_kwargs)
  File "/home/airflow/.local/lib/python3.8/site-packages/airflow/models/taskinstance.py", line 414, in _execute_callable
    return execute_callable(context=context, **execute_callable_kwargs)
  File "/home/airflow/.local/lib/python3.8/site-packages/airflow/operators/python.py", line 200, in execute
    return_value = self.execute_callable()
  File "/home/airflow/.local/lib/python3.8/site-packages/airflow/operators/python.py", line 217, in execute_callable
    return self.python_callable(*self.op_args, **self.op_kwargs)
  File "/opt/airflow/dags/components/gold/model_training/model_training.py", line 56, in forecast_model_training
    df['date'] = pd.to_datetime(df['date'], format='%d/%m/%Y')
UnboundLocalError: local variable 'df' referenced before assignment
[2024-10-04T05:10:32.040+0000] {taskinstance.py:1149} INFO - Marking task as FAILED. dag_id=Gold_training_Pipeline, task_id=model_training, execution_date=20241004T050956, start_date=20241004T051031, end_date=20241004T051032
[2024-10-04T05:10:32.044+0000] {logging_mixin.py:188} WARNING - /home/***/.local/lib/python3.8/site-packages/***/utils/context.py:207 AirflowContextDeprecationWarning: Accessing 'execution_date' from the template is deprecated and will be removed in a future version. Please use 'data_interval_start' or 'logical_date' instead.
[2024-10-04T05:10:32.049+0000] {logging_mixin.py:188} WARNING - /home/***/.local/lib/python3.8/site-packages/***/utils/email.py:154 RemovedInAirflow3Warning: Fetching SMTP credentials from configuration variables will be deprecated in a future release. Please set credentials using a connection instead.
[2024-10-04T05:10:32.049+0000] {email.py:270} INFO - Email alerting: attempt 1
[2024-10-04T05:10:34.190+0000] {email.py:281} INFO - Sent an alert email to ['deshanariyarathna@gmail.com']
[2024-10-04T05:10:36.049+0000] {standard_task_runner.py:107} ERROR - Failed to execute job 244 for task model_training (local variable 'df' referenced before assignment; 2281)
[2024-10-04T05:10:36.082+0000] {local_task_job_runner.py:234} INFO - Task exited with return code 1
[2024-10-04T05:10:36.094+0000] {taskinstance.py:3312} INFO - 0 downstream tasks scheduled from follow-on schedule check
