[2024-10-04T05:12:25.808+0000] {taskinstance.py:1979} INFO - Dependencies all met for dep_context=non-requeueable deps ti=<TaskInstance: Gold_training_Pipeline.model_training manual__2024-10-04T05:12:11.778715+00:00 [queued]>
[2024-10-04T05:12:25.907+0000] {taskinstance.py:1979} INFO - Dependencies all met for dep_context=requeueable deps ti=<TaskInstance: Gold_training_Pipeline.model_training manual__2024-10-04T05:12:11.778715+00:00 [queued]>
[2024-10-04T05:12:25.908+0000] {taskinstance.py:2193} INFO - Starting attempt 1 of 4
[2024-10-04T05:12:25.920+0000] {taskinstance.py:2217} INFO - Executing <Task(PythonOperator): model_training> on 2024-10-04 05:12:11.778715+00:00
[2024-10-04T05:12:25.928+0000] {standard_task_runner.py:60} INFO - Started process 2588 to run task
[2024-10-04T05:12:25.930+0000] {standard_task_runner.py:87} INFO - Running: ['***', 'tasks', 'run', 'Gold_training_Pipeline', 'model_training', 'manual__2024-10-04T05:12:11.778715+00:00', '--job-id', '247', '--raw', '--subdir', 'DAGS_FOLDER/gold_training_pipeline.py', '--cfg-path', '/tmp/tmpiym0r6r3']
[2024-10-04T05:12:25.933+0000] {standard_task_runner.py:88} INFO - Job 247: Subtask model_training
[2024-10-04T05:12:25.970+0000] {task_command.py:423} INFO - Running <TaskInstance: Gold_training_Pipeline.model_training manual__2024-10-04T05:12:11.778715+00:00 [running]> on host 7277d8e72c00
[2024-10-04T05:12:26.039+0000] {taskinstance.py:2513} INFO - Exporting env vars: AIRFLOW_CTX_DAG_OWNER='sdeshan' AIRFLOW_CTX_DAG_ID='Gold_training_Pipeline' AIRFLOW_CTX_TASK_ID='model_training' AIRFLOW_CTX_EXECUTION_DATE='2024-10-04T05:12:11.778715+00:00' AIRFLOW_CTX_TRY_NUMBER='1' AIRFLOW_CTX_DAG_RUN_ID='manual__2024-10-04T05:12:11.778715+00:00'
[2024-10-04T05:12:26.102+0000] {taskinstance.py:2731} ERROR - Task failed with exception
Traceback (most recent call last):
  File "/home/airflow/.local/lib/python3.8/site-packages/airflow/models/taskinstance.py", line 444, in _execute_task
    result = _execute_callable(context=context, **execute_callable_kwargs)
  File "/home/airflow/.local/lib/python3.8/site-packages/airflow/models/taskinstance.py", line 414, in _execute_callable
    return execute_callable(context=context, **execute_callable_kwargs)
  File "/home/airflow/.local/lib/python3.8/site-packages/airflow/operators/python.py", line 200, in execute
    return_value = self.execute_callable()
  File "/home/airflow/.local/lib/python3.8/site-packages/airflow/operators/python.py", line 217, in execute_callable
    return self.python_callable(*self.op_args, **self.op_kwargs)
  File "/opt/airflow/dags/components/gold/model_training/model_training.py", line 70, in forecast_model_training
    prophet_model.fit(df[['ds', 'y'] + regressors])
  File "/home/airflow/.local/lib/python3.8/site-packages/pandas/core/frame.py", line 3767, in __getitem__
    indexer = self.columns._get_indexer_strict(key, "columns")[1]
  File "/home/airflow/.local/lib/python3.8/site-packages/pandas/core/indexes/base.py", line 5877, in _get_indexer_strict
    self._raise_if_missing(keyarr, indexer, axis_name)
  File "/home/airflow/.local/lib/python3.8/site-packages/pandas/core/indexes/base.py", line 5941, in _raise_if_missing
    raise KeyError(f"{not_found} not in index")
KeyError: "['s&p_500_index'] not in index"
[2024-10-04T05:12:26.126+0000] {taskinstance.py:1149} INFO - Marking task as UP_FOR_RETRY. dag_id=Gold_training_Pipeline, task_id=model_training, execution_date=20241004T051211, start_date=20241004T051225, end_date=20241004T051226
[2024-10-04T05:12:26.138+0000] {standard_task_runner.py:107} ERROR - Failed to execute job 247 for task model_training ("['s&p_500_index'] not in index"; 2588)
[2024-10-04T05:12:26.184+0000] {local_task_job_runner.py:234} INFO - Task exited with return code 1
[2024-10-04T05:12:26.199+0000] {taskinstance.py:3312} INFO - 0 downstream tasks scheduled from follow-on schedule check
