[2024-10-10T09:36:33.441+0000] {taskinstance.py:1979} INFO - Dependencies all met for dep_context=non-requeueable deps ti=<TaskInstance: Gold_training_Pipeline.send_mails manual__2024-10-10T09:35:12.086559+00:00 [queued]>
[2024-10-10T09:36:33.446+0000] {taskinstance.py:1979} INFO - Dependencies all met for dep_context=requeueable deps ti=<TaskInstance: Gold_training_Pipeline.send_mails manual__2024-10-10T09:35:12.086559+00:00 [queued]>
[2024-10-10T09:36:33.447+0000] {taskinstance.py:2193} INFO - Starting attempt 2 of 4
[2024-10-10T09:36:33.456+0000] {taskinstance.py:2217} INFO - Executing <Task(PythonOperator): send_mails> on 2024-10-10 09:35:12.086559+00:00
[2024-10-10T09:36:33.462+0000] {standard_task_runner.py:60} INFO - Started process 4990 to run task
[2024-10-10T09:36:33.464+0000] {standard_task_runner.py:87} INFO - Running: ['***', 'tasks', 'run', 'Gold_training_Pipeline', 'send_mails', 'manual__2024-10-10T09:35:12.086559+00:00', '--job-id', '419', '--raw', '--subdir', 'DAGS_FOLDER/gold_training_pipeline.py', '--cfg-path', '/tmp/tmpkw2qn3_e']
[2024-10-10T09:36:33.465+0000] {standard_task_runner.py:88} INFO - Job 419: Subtask send_mails
[2024-10-10T09:36:33.508+0000] {task_command.py:423} INFO - Running <TaskInstance: Gold_training_Pipeline.send_mails manual__2024-10-10T09:35:12.086559+00:00 [running]> on host 3c39c54b31c0
[2024-10-10T09:36:33.565+0000] {taskinstance.py:2513} INFO - Exporting env vars: AIRFLOW_CTX_DAG_OWNER='sdeshan' AIRFLOW_CTX_DAG_ID='Gold_training_Pipeline' AIRFLOW_CTX_TASK_ID='send_mails' AIRFLOW_CTX_EXECUTION_DATE='2024-10-10T09:35:12.086559+00:00' AIRFLOW_CTX_TRY_NUMBER='2' AIRFLOW_CTX_DAG_RUN_ID='manual__2024-10-10T09:35:12.086559+00:00'
[2024-10-10T09:36:33.569+0000] {taskinstance.py:2731} ERROR - Task failed with exception
Traceback (most recent call last):
  File "/home/airflow/.local/lib/python3.8/site-packages/airflow/models/taskinstance.py", line 444, in _execute_task
    result = _execute_callable(context=context, **execute_callable_kwargs)
  File "/home/airflow/.local/lib/python3.8/site-packages/airflow/models/taskinstance.py", line 414, in _execute_callable
    return execute_callable(context=context, **execute_callable_kwargs)
  File "/home/airflow/.local/lib/python3.8/site-packages/airflow/operators/python.py", line 200, in execute
    return_value = self.execute_callable()
  File "/home/airflow/.local/lib/python3.8/site-packages/airflow/operators/python.py", line 217, in execute_callable
    return self.python_callable(*self.op_args, **self.op_kwargs)
  File "/opt/airflow/dags/components/gold/post_training/sending_mails.py", line 36, in mail_sending
    cur.execute(query)
psycopg2.errors.UndefinedTable: relation "weekly_report" does not exist
LINE 1: SELECT * FROM weekly_report
                      ^

[2024-10-10T09:36:33.577+0000] {taskinstance.py:1149} INFO - Marking task as UP_FOR_RETRY. dag_id=Gold_training_Pipeline, task_id=send_mails, execution_date=20241010T093512, start_date=20241010T093633, end_date=20241010T093633
[2024-10-10T09:36:33.599+0000] {standard_task_runner.py:107} ERROR - Failed to execute job 419 for task send_mails (relation "weekly_report" does not exist
LINE 1: SELECT * FROM weekly_report
                      ^
; 4990)
[2024-10-10T09:36:33.637+0000] {local_task_job_runner.py:234} INFO - Task exited with return code 1
[2024-10-10T09:36:33.649+0000] {taskinstance.py:3312} INFO - 0 downstream tasks scheduled from follow-on schedule check
