[2024-10-10T09:36:27.639+0000] {taskinstance.py:1979} INFO - Dependencies all met for dep_context=non-requeueable deps ti=<TaskInstance: Gold_training_Pipeline.send_mails manual__2024-10-09T10:42:12.899974+00:00 [queued]>
[2024-10-10T09:36:27.645+0000] {taskinstance.py:1979} INFO - Dependencies all met for dep_context=requeueable deps ti=<TaskInstance: Gold_training_Pipeline.send_mails manual__2024-10-09T10:42:12.899974+00:00 [queued]>
[2024-10-10T09:36:27.646+0000] {taskinstance.py:2193} INFO - Starting attempt 4 of 4
[2024-10-10T09:36:27.660+0000] {taskinstance.py:2217} INFO - Executing <Task(PythonOperator): send_mails> on 2024-10-09 10:42:12.899974+00:00
[2024-10-10T09:36:27.668+0000] {standard_task_runner.py:60} INFO - Started process 4899 to run task
[2024-10-10T09:36:27.670+0000] {standard_task_runner.py:87} INFO - Running: ['***', 'tasks', 'run', 'Gold_training_Pipeline', 'send_mails', 'manual__2024-10-09T10:42:12.899974+00:00', '--job-id', '414', '--raw', '--subdir', 'DAGS_FOLDER/gold_training_pipeline.py', '--cfg-path', '/tmp/tmpob1xn5t8']
[2024-10-10T09:36:27.671+0000] {standard_task_runner.py:88} INFO - Job 414: Subtask send_mails
[2024-10-10T09:36:27.704+0000] {task_command.py:423} INFO - Running <TaskInstance: Gold_training_Pipeline.send_mails manual__2024-10-09T10:42:12.899974+00:00 [running]> on host 3c39c54b31c0
[2024-10-10T09:36:27.773+0000] {taskinstance.py:2513} INFO - Exporting env vars: AIRFLOW_CTX_DAG_OWNER='sdeshan' AIRFLOW_CTX_DAG_ID='Gold_training_Pipeline' AIRFLOW_CTX_TASK_ID='send_mails' AIRFLOW_CTX_EXECUTION_DATE='2024-10-09T10:42:12.899974+00:00' AIRFLOW_CTX_TRY_NUMBER='4' AIRFLOW_CTX_DAG_RUN_ID='manual__2024-10-09T10:42:12.899974+00:00'
[2024-10-10T09:36:27.778+0000] {taskinstance.py:2731} ERROR - Task failed with exception
Traceback (most recent call last):
  File "/home/airflow/.local/lib/python3.8/site-packages/airflow/models/taskinstance.py", line 444, in _execute_task
    result = _execute_callable(context=context, **execute_callable_kwargs)
  File "/home/airflow/.local/lib/python3.8/site-packages/airflow/models/taskinstance.py", line 414, in _execute_callable
    return execute_callable(context=context, **execute_callable_kwargs)
  File "/home/airflow/.local/lib/python3.8/site-packages/airflow/operators/python.py", line 200, in execute
    return_value = self.execute_callable()
  File "/home/airflow/.local/lib/python3.8/site-packages/airflow/operators/python.py", line 217, in execute_callable
    return self.python_callable(*self.op_args, **self.op_kwargs)
  File "/opt/airflow/dags/components/gold/post_training/sending_mails.py", line 36, in mail_sending
    cur.execute(query)
psycopg2.errors.UndefinedTable: relation "weekly_report" does not exist
LINE 1: SELECT * FROM weekly_report
                      ^

[2024-10-10T09:36:27.790+0000] {taskinstance.py:1149} INFO - Marking task as FAILED. dag_id=Gold_training_Pipeline, task_id=send_mails, execution_date=20241009T104212, start_date=20241010T093627, end_date=20241010T093627
[2024-10-10T09:36:27.794+0000] {logging_mixin.py:188} WARNING - /home/***/.local/lib/python3.8/site-packages/***/utils/context.py:207 AirflowContextDeprecationWarning: Accessing 'execution_date' from the template is deprecated and will be removed in a future version. Please use 'data_interval_start' or 'logical_date' instead.
[2024-10-10T09:36:27.797+0000] {logging_mixin.py:188} WARNING - /home/***/.local/lib/python3.8/site-packages/***/utils/email.py:154 RemovedInAirflow3Warning: Fetching SMTP credentials from configuration variables will be deprecated in a future release. Please set credentials using a connection instead.
[2024-10-10T09:36:27.798+0000] {email.py:270} INFO - Email alerting: attempt 1
[2024-10-10T09:36:30.475+0000] {email.py:281} INFO - Sent an alert email to ['deshanariyarathna@gmail.com']
[2024-10-10T09:36:34.081+0000] {standard_task_runner.py:107} ERROR - Failed to execute job 414 for task send_mails (relation "weekly_report" does not exist
LINE 1: SELECT * FROM weekly_report
                      ^
; 4899)
[2024-10-10T09:36:34.105+0000] {local_task_job_runner.py:234} INFO - Task exited with return code 1
[2024-10-10T09:36:34.116+0000] {taskinstance.py:3312} INFO - 0 downstream tasks scheduled from follow-on schedule check
