[2024-10-21T11:32:48.136+0000] {taskinstance.py:1979} INFO - Dependencies all met for dep_context=non-requeueable deps ti=<TaskInstance: Vehicle_Model_Training_Pipeline.model_training_honda manual__2024-10-21T11:32:21.093035+00:00 [queued]>
[2024-10-21T11:32:48.143+0000] {taskinstance.py:1979} INFO - Dependencies all met for dep_context=requeueable deps ti=<TaskInstance: Vehicle_Model_Training_Pipeline.model_training_honda manual__2024-10-21T11:32:21.093035+00:00 [queued]>
[2024-10-21T11:32:48.144+0000] {taskinstance.py:2193} INFO - Starting attempt 3 of 4
[2024-10-21T11:32:48.153+0000] {taskinstance.py:2217} INFO - Executing <Task(PythonOperator): model_training_honda> on 2024-10-21 11:32:21.093035+00:00
[2024-10-21T11:32:48.160+0000] {standard_task_runner.py:60} INFO - Started process 40552 to run task
[2024-10-21T11:32:48.162+0000] {standard_task_runner.py:87} INFO - Running: ['***', 'tasks', 'run', 'Vehicle_Model_Training_Pipeline', 'model_training_honda', 'manual__2024-10-21T11:32:21.093035+00:00', '--job-id', '146', '--raw', '--subdir', 'DAGS_FOLDER/vehicle_model_training_pipeline.py', '--cfg-path', '/tmp/tmprqdo3pqr']
[2024-10-21T11:32:48.167+0000] {standard_task_runner.py:88} INFO - Job 146: Subtask model_training_honda
[2024-10-21T11:32:48.207+0000] {task_command.py:423} INFO - Running <TaskInstance: Vehicle_Model_Training_Pipeline.model_training_honda manual__2024-10-21T11:32:21.093035+00:00 [running]> on host 988c1a0779ad
[2024-10-21T11:32:48.256+0000] {taskinstance.py:2513} INFO - Exporting env vars: AIRFLOW_CTX_DAG_OWNER='sdeshan' AIRFLOW_CTX_DAG_ID='Vehicle_Model_Training_Pipeline' AIRFLOW_CTX_TASK_ID='model_training_honda' AIRFLOW_CTX_EXECUTION_DATE='2024-10-21T11:32:21.093035+00:00' AIRFLOW_CTX_TRY_NUMBER='3' AIRFLOW_CTX_DAG_RUN_ID='manual__2024-10-21T11:32:21.093035+00:00'
[2024-10-21T11:32:48.260+0000] {taskinstance.py:2731} ERROR - Task failed with exception
Traceback (most recent call last):
  File "/home/airflow/.local/lib/python3.8/site-packages/airflow/models/taskinstance.py", line 444, in _execute_task
    result = _execute_callable(context=context, **execute_callable_kwargs)
  File "/home/airflow/.local/lib/python3.8/site-packages/airflow/models/taskinstance.py", line 414, in _execute_callable
    return execute_callable(context=context, **execute_callable_kwargs)
  File "/home/airflow/.local/lib/python3.8/site-packages/airflow/operators/python.py", line 200, in execute
    return_value = self.execute_callable()
  File "/home/airflow/.local/lib/python3.8/site-packages/airflow/operators/python.py", line 217, in execute_callable
    return self.python_callable(*self.op_args, **self.op_kwargs)
  File "/opt/airflow/dags/components/vehicle/model_training_components/model_training.py", line 34, in train_model
    cur.execute(query)
psycopg2.errors.UndefinedTable: relation "honda_train_data" does not exist
LINE 1: SELECT * FROM HONDA_train_data
                      ^

[2024-10-21T11:32:48.275+0000] {taskinstance.py:1149} INFO - Marking task as UP_FOR_RETRY. dag_id=Vehicle_Model_Training_Pipeline, task_id=model_training_honda, execution_date=20241021T113221, start_date=20241021T113248, end_date=20241021T113248
[2024-10-21T11:32:48.284+0000] {standard_task_runner.py:107} ERROR - Failed to execute job 146 for task model_training_honda (relation "honda_train_data" does not exist
LINE 1: SELECT * FROM HONDA_train_data
                      ^
; 40552)
[2024-10-21T11:32:48.295+0000] {local_task_job_runner.py:234} INFO - Task exited with return code 1
[2024-10-21T11:32:48.309+0000] {taskinstance.py:3312} INFO - 0 downstream tasks scheduled from follow-on schedule check
