[2024-08-21T06:54:35.833+0000] {taskinstance.py:1979} INFO - Dependencies all met for dep_context=non-requeueable deps ti=<TaskInstance: Vehicle_Model_Training_Pipeline.model_training_micro manual__2024-08-21T06:54:14.631777+00:00 [queued]>
[2024-08-21T06:54:35.841+0000] {taskinstance.py:1979} INFO - Dependencies all met for dep_context=requeueable deps ti=<TaskInstance: Vehicle_Model_Training_Pipeline.model_training_micro manual__2024-08-21T06:54:14.631777+00:00 [queued]>
[2024-08-21T06:54:35.842+0000] {taskinstance.py:2193} INFO - Starting attempt 2 of 4
[2024-08-21T06:54:35.854+0000] {taskinstance.py:2217} INFO - Executing <Task(PythonOperator): model_training_micro> on 2024-08-21 06:54:14.631777+00:00
[2024-08-21T06:54:35.860+0000] {standard_task_runner.py:60} INFO - Started process 403 to run task
[2024-08-21T06:54:35.862+0000] {standard_task_runner.py:87} INFO - Running: ['***', 'tasks', 'run', 'Vehicle_Model_Training_Pipeline', 'model_training_micro', 'manual__2024-08-21T06:54:14.631777+00:00', '--job-id', '68', '--raw', '--subdir', 'DAGS_FOLDER/vehicle_model_training_pipeline.py', '--cfg-path', '/tmp/tmpoy_elyvs']
[2024-08-21T06:54:35.864+0000] {standard_task_runner.py:88} INFO - Job 68: Subtask model_training_micro
[2024-08-21T06:54:35.906+0000] {task_command.py:423} INFO - Running <TaskInstance: Vehicle_Model_Training_Pipeline.model_training_micro manual__2024-08-21T06:54:14.631777+00:00 [running]> on host 24901b22bab2
[2024-08-21T06:54:35.962+0000] {taskinstance.py:2513} INFO - Exporting env vars: AIRFLOW_CTX_DAG_OWNER='sdeshan' AIRFLOW_CTX_DAG_ID='Vehicle_Model_Training_Pipeline' AIRFLOW_CTX_TASK_ID='model_training_micro' AIRFLOW_CTX_EXECUTION_DATE='2024-08-21T06:54:14.631777+00:00' AIRFLOW_CTX_TRY_NUMBER='2' AIRFLOW_CTX_DAG_RUN_ID='manual__2024-08-21T06:54:14.631777+00:00'
[2024-08-21T06:54:35.973+0000] {logging_mixin.py:188} INFO - error [Errno 2] No such file or directory: 'artifacts/preprocessor.pkl'
[2024-08-21T06:54:35.976+0000] {taskinstance.py:2731} ERROR - Task failed with exception
Traceback (most recent call last):
  File "/home/airflow/.local/lib/python3.8/site-packages/airflow/models/taskinstance.py", line 444, in _execute_task
    result = _execute_callable(context=context, **execute_callable_kwargs)
  File "/home/airflow/.local/lib/python3.8/site-packages/airflow/models/taskinstance.py", line 414, in _execute_callable
    return execute_callable(context=context, **execute_callable_kwargs)
  File "/home/airflow/.local/lib/python3.8/site-packages/airflow/operators/python.py", line 200, in execute
    return_value = self.execute_callable()
  File "/home/airflow/.local/lib/python3.8/site-packages/airflow/operators/python.py", line 217, in execute_callable
    return self.python_callable(*self.op_args, **self.op_kwargs)
  File "/opt/airflow/dags/components/vehicle/model_training_components/model_training.py", line 63, in train_model
    input_feature_train_arr=preprocessor.fit_transform(input_feature_train_df)
AttributeError: 'NoneType' object has no attribute 'fit_transform'
[2024-08-21T06:54:35.998+0000] {taskinstance.py:1149} INFO - Marking task as UP_FOR_RETRY. dag_id=Vehicle_Model_Training_Pipeline, task_id=model_training_micro, execution_date=20240821T065414, start_date=20240821T065435, end_date=20240821T065435
[2024-08-21T06:54:36.008+0000] {standard_task_runner.py:107} ERROR - Failed to execute job 68 for task model_training_micro ('NoneType' object has no attribute 'fit_transform'; 403)
[2024-08-21T06:54:36.037+0000] {local_task_job_runner.py:234} INFO - Task exited with return code 1
[2024-08-21T06:54:36.048+0000] {taskinstance.py:3312} INFO - 0 downstream tasks scheduled from follow-on schedule check
