[2024-10-10T09:36:36.945+0000] {taskinstance.py:1979} INFO - Dependencies all met for dep_context=non-requeueable deps ti=<TaskInstance: Gold_training_Pipeline.send_mails scheduled__2024-10-08T00:00:00+00:00 [queued]>
[2024-10-10T09:36:36.950+0000] {taskinstance.py:1979} INFO - Dependencies all met for dep_context=requeueable deps ti=<TaskInstance: Gold_training_Pipeline.send_mails scheduled__2024-10-08T00:00:00+00:00 [queued]>
[2024-10-10T09:36:36.951+0000] {taskinstance.py:2193} INFO - Starting attempt 3 of 4
[2024-10-10T09:36:36.980+0000] {taskinstance.py:2217} INFO - Executing <Task(PythonOperator): send_mails> on 2024-10-08 00:00:00+00:00
[2024-10-10T09:36:36.987+0000] {standard_task_runner.py:60} INFO - Started process 5070 to run task
[2024-10-10T09:36:36.989+0000] {standard_task_runner.py:87} INFO - Running: ['***', 'tasks', 'run', 'Gold_training_Pipeline', 'send_mails', 'scheduled__2024-10-08T00:00:00+00:00', '--job-id', '421', '--raw', '--subdir', 'DAGS_FOLDER/gold_training_pipeline.py', '--cfg-path', '/tmp/tmp2fppi712']
[2024-10-10T09:36:36.990+0000] {standard_task_runner.py:88} INFO - Job 421: Subtask send_mails
[2024-10-10T09:36:37.033+0000] {task_command.py:423} INFO - Running <TaskInstance: Gold_training_Pipeline.send_mails scheduled__2024-10-08T00:00:00+00:00 [running]> on host 3c39c54b31c0
[2024-10-10T09:36:37.093+0000] {taskinstance.py:2513} INFO - Exporting env vars: AIRFLOW_CTX_DAG_OWNER='sdeshan' AIRFLOW_CTX_DAG_ID='Gold_training_Pipeline' AIRFLOW_CTX_TASK_ID='send_mails' AIRFLOW_CTX_EXECUTION_DATE='2024-10-08T00:00:00+00:00' AIRFLOW_CTX_TRY_NUMBER='3' AIRFLOW_CTX_DAG_RUN_ID='scheduled__2024-10-08T00:00:00+00:00'
[2024-10-10T09:36:37.096+0000] {taskinstance.py:2731} ERROR - Task failed with exception
Traceback (most recent call last):
  File "/home/airflow/.local/lib/python3.8/site-packages/airflow/models/taskinstance.py", line 444, in _execute_task
    result = _execute_callable(context=context, **execute_callable_kwargs)
  File "/home/airflow/.local/lib/python3.8/site-packages/airflow/models/taskinstance.py", line 414, in _execute_callable
    return execute_callable(context=context, **execute_callable_kwargs)
  File "/home/airflow/.local/lib/python3.8/site-packages/airflow/operators/python.py", line 200, in execute
    return_value = self.execute_callable()
  File "/home/airflow/.local/lib/python3.8/site-packages/airflow/operators/python.py", line 217, in execute_callable
    return self.python_callable(*self.op_args, **self.op_kwargs)
  File "/opt/airflow/dags/components/gold/post_training/sending_mails.py", line 36, in mail_sending
    cur.execute(query)
psycopg2.errors.UndefinedTable: relation "weekly_report" does not exist
LINE 1: SELECT * FROM weekly_report
                      ^

[2024-10-10T09:36:37.106+0000] {taskinstance.py:1149} INFO - Marking task as UP_FOR_RETRY. dag_id=Gold_training_Pipeline, task_id=send_mails, execution_date=20241008T000000, start_date=20241010T093636, end_date=20241010T093637
[2024-10-10T09:36:37.126+0000] {standard_task_runner.py:107} ERROR - Failed to execute job 421 for task send_mails (relation "weekly_report" does not exist
LINE 1: SELECT * FROM weekly_report
                      ^
; 5070)
[2024-10-10T09:36:37.167+0000] {local_task_job_runner.py:234} INFO - Task exited with return code 1
[2024-10-10T09:36:37.183+0000] {taskinstance.py:3312} INFO - 0 downstream tasks scheduled from follow-on schedule check
